Workbook
Name am: Annuity!$C$1
Name gr: Annuity!$C$3
Name ir: Annuity!$C$5
Name per: Annuity!$C$2
Name pi: Annuity!$E$2

Sheet Data
B2: MƏLUMAT PƏNCƏRƏSİ
E3: Kreditin verilmə tarixi | H3: № Müqavilə
E5: 45768 | F5: 20.04.2025 | I5: 04/2078-25
E7: Kreditin son tarixi
E9: =IF(Data!C78<=6,Лист2!M21,IF(Data!C78<=12,Лист2!M22,IF(Data!C78<=18,Лист2!M23,IF(Data!C78<=24,Лист2!M24,0)))) -> 46133 | H9: 7 | K9: GA-2.2.
F11: LA-3.2.6. | H11: 0 | J11: % | K11: LA-2.2.
E13: =C76 -> 0 | F13: LA-3.3.3. | H13: =E13*2 -> 0 | J13: % | K13: LA-2.7.
E15: 7 | F15: LA-3.3.3. | H15: 1 | J15: % | K15: LA-2.6.
E17: =E13 -> 0 | H17: 3 | K17: LA-7.2.
K18: GA-2.2.
B19: Borcalanın rekvizitləri | C19: seriya nömrəsi | E19: verilmə tarixi | F19: fin kod
A21: TRUE | B21: Şəxsiyyət vəsiqəsi | C21: AA5512135 | E21: 29.10.2023 | F21: 6AEE7KZ
B23: Borcalan Haqında | C23: Yunusov Vüqar Fikrət oğlu
B25: Borcalan haqında | C25: =C23 -> Yunusov Vüqar Fikrət oğlu
B27: Kim tərəfindən verilib | C27: Asan4
B29: Qeydiyyat ünvanı | C29: NEFTÇALA RAYONU, XOL QARABUCAQ Ə/D, DÖRDLƏR KƏNDİ
B31: faktiki yaşayış ünvanı | C31: Sabunçu ray., Kürdəxanı qəs,Elton İsgəndərov küç,23-cü məhəllə, (113 nömrəli məktəb tərəf)
B33: Telefonlar | C33: 0703732363 müştəri,
B35: Doğum yeri və tarixi | C35: Azərbaycan | D35: Bakı | E35: 25.12.1964
B37: Vətəndaşlığı | C37: Azərbaycanlı
B39: Ailə vəziyəti | C39: Evli
B41: Təhsili | C41: Orta
B43: İşlədiyi yerin hüquqi adı | C43: Fərdi gəlirlər
B45: İşlədiyi yerin ünvanı | C45: Bakı
B47: Tutdulduğu vəzifə və staj | C47: Diş texniki
B49: Aylıq əmək haqqı | C49: 1500 | E49: Ödənilmə mənbələri | F49: Əmək haqqı
B51: Digər gəlirlərin cəmi | C51: 0 | E51: Kart nömrəsi
B53: Ailə gəlirləri | C53: 500
B55: Xərclərin cəmi | C55: 1500
B57: Xalis gəlir (ixrac) | C57: =C49+C51+C53-C55 -> 500
B59: Uşaqların sayı və təvəllüdü | C59: 2
B61: BOKT aidiyyatı olan şəxs | C61: Yox
B63: Müəssisənin mülkiyyət forması | D63: Fiziki şəxs
B65: Fəaliyyət növü (borcalan fiziki şəxsdirsə məşquliyyət növü) | D65: Əmək haqqı
B67: 2200
B68: Kreditin məqsədi | C68: İstehlak mal(lar)ının alınması üçün
K69: 3
A70: Qeyriqənəatbəxş | B70: Maliyə Təhlili | C70: =A72 -> Qənaətbəxş | E70: =A72 -> Qənaətbəxş | K70: 3
K71: 3
A72: Qənaətbəxş | B72: Digər şərtlər | C72: yoxdur
...

Sheet Ərizə
W6: BOKT "İDEAL KREDİT" MMC
W7: Partnyorluq kreditləri bölməsinin müdiri Vüsal Şirməmmədov
W8: =Data!C29 -> NEFTÇALA RAYONU, XOL QARABUCAQ Ə/D, DÖRDLƏR KƏNDİ
W10: ünvanda qeydiyyatda olan fiziki şəxs
W11: =Data!C23 -> Yunusov Vüqar Fikrət oğlu
W12: (şəxsiyyət vəsiqəsi № | AI12: =Data!C21 -> AA5512135
AM13: =Data!E21 -> 29.10.2023 | AT13: )
N24: ƏRİZƏ
F26: Yazıb sizdən xahiş edirəm ki, | T26: =Data!C68 -> İstehlak mal(lar)ının alınması üçün | AO26: mənə | AR26: =Data!C78 -> 12 | AU26: ay
C28: müddətinə | I28: =Data!C74 -> 1272 | R28: =PP!AK6 -> (Bir min iki yüz yetmiş iki manat ) | AQ28: məbləğində
C30: kredit verəsiniz.
C36: =Data!C25 -> Yunusov Vüqar Fikrət oğlu | AE36: =Data!F5 -> 20.04.2025 | AP36: cü il

Sheet PP
I1: Ödəniş qaydası: Bank xidmətləri - İDEAL KREDİT
J3: Ödəniş etmək üçün məlumatlar
J4: FİN kod: | L4: =Data!F21 -> 6AEE7KZ
C5: VÖEN: | D5: 1300480591 | J5: Doğum tarixi: | L5: =Data!E35 -> 25.12.1964 | Y5: =TODAY() -> 45786
D6: ÖDƏNİŞ QRAFİKİ | J6: Ödəniş sistemləri ilə ödəmək üçün | Y6: =IF(MONTH(Y5)=1,"йанвар",(IF(MONTH(Y5)=2,"феврал",(IF(MONTH(Y5)=3,"март",(IF(MONTH(Y5)=4,"апрел",(IF(MONTH(Y5)=5,"май",(IF(MONTH(Y5)=6,"ийун",(IF(MONTH(Y5)=7,"ийул",""))))))))))))) -> май | AK6: =CONCATENATE("(",R16,")") -> (Bir min iki yüz yetmiş iki manat )
C7: =Data!I5 -> 04/2078-25 | D7: saylı kredit müqaviləsinə 1 Saylı əlavə | S7: Ссуданын юдянилмяси цчцн | Y7: =IF(Y6="",(IF(MONTH(Y5)=8,"август",(IF(MONTH(Y5)=9,"сентйабр",(IF(MONTH(Y5)=10,"октйабр",(IF(MONTH(Y5)=11,"нойабр",(IF(MONTH(Y5)=12,"декабр","")))))))))),"")
S8: Фаизин юдянилмяси цчцн | Y8: =YEAR(Y5) -> 2025
C9: Tarix: | D9: =Data!E5 -> 45768 | S9: Пластик карт кредити цзря юдяниш
C10: Məbləğ: | D10: =Data!C74 -> 1272 | E10: AZN | R10: =D10 -> 1272
C11: İllik faiz: | D11: =Data!C76 -> 0 | E11: % | J11: Bank Hesablarımıza ödəmək üçün | P11: =Data!C86 -> 20 | R11: =INT(R10/10000000000) -> 0 | S11: =INT(R10/1000000000)-R11*10 -> 0 | U11: =INT(R10/100000000)-(S11*10+R11*100) -> 0 | W11: =INT(R10/10000000)-(U11*10+S11*100+R11*1000) -> 0 | X11: =INT(R10/1000000)-(R11*10000+S11*1000+U11*100+W11*10) -> 0 | Z11: =INT(R10/100000)-(R11*100000+S11*10000+U11*1000+W11*100+X11*10) -> 0 | AB11: =INT(R10/10000)-(R11*1000000+S11*100000+U11*10000+W11*1000+X11*100+Z11*10) -> 0 | AC11: =INT(R10/1000)-(R11*10000000+S11*1000000+U11*100000+W11*10000+X11*1000+Z11*100+AB11*10) -> 1 | AE11: =INT(R10/100)-(R11*100000000+S11*10000000+U11*1000000+W11*100000+X11*10000+Z11*1000+AB11*100+AC11*10) -> 2 | AG11: =INT(R10/10)-(R11*1000000000+S11*100000000+U11*10000000+W11*1000000+X11*100000+Z11*10000+AB11*1000+AC11*100+AE11*10) -> 7 | AH11: =INT(R10)-(R11*10000000000+S11*1000000000+U11*100000000+W11*10000000+X11*1000000+Z11*100000+AB11*10000+AC11*1000+AE11*100+AG11*10) -> 2 | AI11: =INT(R10*10)-(R11*100000000000+S11*10000000000+U11*1000000000+W11*100000000+X11*10000000+Z11*1000000+AB11*100000+AC11*10000+AE11*1000+AG11*100+AH11*10) -> 0 | AJ11: =INT(R10*100)-(R11*1000000000000+S11*100000000000+U11*10000000000+W11*1000000000+X11*100000000+Z11*10000000+AB11*1000000+AC11*100000+AE11*10000+AG11*1000+AH11*100+AI11*10) -> 0
C12: Müddət: | D12: =Data!C78 -> 12 | E12: ay | J12: Azərpoçt MMC PF 1 | P12: =(Data!C74+(Data!C74*Data!C86%)+Data!C88+G78) -> 1526.4 | R12: =IF(R11=0," ",IF(R11=1," On ",IF(R11=2," İyirmi",IF(R11=3," Otuz",IF(R11=4," Qırx"," ")))))&IF(R11=5," Əlli",IF(R11=6," Altmış",IF(R11=7," Yetmiş",IF(R11=8," Səksən",IF(R11=9," Doxsan"," "))))) | S12: =IF(S11=0," ",IF(S11=1," bir",IF(S11=2," iki",IF(S11=3," üç",IF(S11=4," dörd"," ")))))&IF(S11=5," beş",IF(S11=6," altı",IF(S11=7," yeddi",IF(S11=8," səkkiz",IF(S11=9," doqquz"," "))))) | T12: =IF(AND(S11=0,R11=0)," "," milyard ") | U12: =IF(U11=0," ",IF(U11=1,"bir ",IF(U11=2,"iki ",IF(U11=3,"üç ",IF(U11=4,"dörd "," ")))))&IF(U11=5,"beş ",IF(U11=6,"altı ",IF(U11=7,"yeddi ",IF(U11=8,"səkkiz ",IF(U11=9,"doqquz "," "))))) | V12: =IF(U12=" "," "," yüz ") | W12: =IF(W11=0," ",IF(W11=1,"on ",IF(W11=2,"iyirmi ",IF(W11=3,"otuz ",IF(W11=4,"qırx "," ")))))&IF(W11=5,"əlli ",IF(W11=6,"altmış ",IF(W11=7,"yetmiş ",IF(W11=8,"səksən ",IF(W11=9,"doxsan "," "))))) | X12: =IF(X11=0," ",IF(X11=1,"bir",IF(X11=2,"iki",IF(X11=3,"üç",IF(X11=4,"dörd"," ")))))&IF(X11=5,"beş",IF(X11=6,"altı",IF(X11=7,"yeddi",IF(X11=8,"səkkiz",IF(X11=9,"doqquz"," "))))) | Y12: =IF(AND(W11=0,U11=0,X11=0)," "," milyon ") | Z12: =IF(Z11=0," ",IF(Z11=1,"bir ",IF(Z11=2,"iki ",IF(Z11=3,"üç ",IF(Z11=4,"dörd "," ")))))&IF(Z11=5,"beş ",IF(Z11=6,"altı ",IF(Z11=7,"yeddi ",IF(Z11=8,"səkkiz ",IF(Z11=9,"doqquz "," "))))) | AA12: =IF(Z12=" "," "," yüz ") | AB12: =IF(AB11=0," ",IF(AB11=1,"on ",IF(AB11=2,"iyirmi ",IF(AB11=3,"otuz ",IF(AB11=4,"qırx "," ")))))&IF(AB11=5,"əlli ",IF(AB11=6,"altmış ",IF(AB11=7,"yetmiş ",IF(AB11=8,"səksən ",IF(AB11=9,"doxsan "," "))))) | AC12: =IF(AC11=0," ",IF(AC11=1,"bir",IF(AC11=2,"iki",IF(AC11=3,"üç",IF(AC11=4,"dörd"," ")))))&IF(AC11=5,"beş",IF(AC11=6,"altı",IF(AC11=7,"yeddi",IF(AC11=8,"səkkiz",IF(AC11=9,"doqquz"," "))))) -> bir | AD12: =IF(AND(AB11=0,Z11=0,AC11=0)," "," min ") -> min | AE12: =IF(AE11=0," ",IF(AE11=1,"bir ",IF(AE11=2,"iki ",IF(AE11=3,"üç ",IF(AE11=4,"dörd "," ")))))&IF(AE11=5,"beş ",IF(AE11=6,"altı ",IF(AE11=7,"yeddi ",IF(AE11=8,"səkkiz ",IF(AE11=9,"doqquz "," "))))) -> iki | AF12: =IF(AE12=" "," "," yüz ") -> yüz | AG12: =IF(AG11=0," ",IF(AG11=1," on",IF(AG11=2," iyirmi",IF(AG11=3," otuz",IF(AG11=4," qırx"," ")))))&IF(AG11=5," əlli",IF(AG11=6," altmış",IF(AG11=7," yetmiş",IF(AG11=8," səksən",IF(AG11=9," doxsan"," "))))) -> yetmiş | AH12: =IF(AH11=0," ",IF(AH11=1," bir",IF(AH11=2," iki",IF(AH11=3," üç",IF(AH11=4," dörd"," ")))))&IF(AH11=5," beş",IF(AH11=6," altı",IF(AH11=7," yeddi",IF(AH11=8," səkkiz",IF(AH11=9," doqquz"," "))))) -> iki | AI12: =IF(AI11=0," ",IF(AI11=1," он",IF(AI11=2," ийирми",IF(AI11=3," отуз",IF(AI11=4," гырх"," ")))))&IF(AI11=5," ялли",IF(AI11=6," алтмыш",IF(AI11=7," йетмиш",IF(AI11=8," сяксян",IF(AI11=9," дохсан"," "))))) | AJ12: =IF(AJ11=0," ",IF(AJ11=1," bir",IF(AJ11=2," iki",IF(AJ11=3," üç",IF(AJ11=4," dörd"," ")))))&IF(AJ11=5," beş",IF(AJ11=6," altı",IF(AJ11=7," yeddi",IF(AJ11=8," səkkiz",IF(AJ11=9," doqquz"," ")))))
C13: Güzəşt müd: | D13: =Data!C80 -> 0 | E13: ay | J13: H/h: AZ05AZPO91015461400420200413 | P13: =P12-D10 -> 254.4 | R13: =PROPER(R12) | S13: =IF(R12=" ",PROPER(S12),S12) | T13: =T12 | U13: =IF(AND(R12=" ",S12=" ",T12=" "),PROPER(U12),U12) | V13: =V12 | W13: =IF(AND(R12=" ",S12=" ",T12=" ",U12=" ",V12=" "),PROPER(W12),W12) | X13: =IF(AND(R12=" ",S12=" ",T12=" ",U12=" ",V12=" ",W12=" "),PROPER(X12),X12) | Y13: =Y12 | Z13: =IF(AND(R12=" ",S12=" ",T12=" ",U12=" ",V12=" ",W12=" ",X12=" ",Y12=" "),PROPER(Z12),Z12) | AA13: =AA12 | AB13: =IF(AND(R12=" ",S12=" ",T12=" ",U12=" ",V12=" ",W12=" ",X12=" ",Y12=" ",Z12=" ",AA12=" "),PROPER(AB12),AB12) | AC13: =IF(AND(R12=" ",S12=" ",T12=" ",U12=" ",V12=" ",W12=" ",X12=" ",Y12=" ",Z12=" ",AA12=" ",AB12=" "),PROPER(AC12),AC12) -> Bir | AD13: =AD12 -> min | AE13: =IF(AND(R12=" ",S12=" ",T12=" ",U12=" ",V12=" ",W12=" ",X12=" ",Y12=" ",Z12=" ",AA12=" ",AB12=" ",AC12=" ",AD12=" "),PROPER(AE12),AE12) -> iki | AF13: =AF12 -> yüz | AG13: =IF(AND(R12=" ",S12=" ",T12=" ",U12=" ",V12=" ",W12=" ",X12=" ",Y12=" ",Z12=" ",AA12=" ",AB12=" ",AC12=" ",AD12=" ",AE12=" ",AF12=" "),PROPER(AG12),AG12) -> yetmiş | AH13: =IF(AND(R12=" ",S12=" ",T12=" ",U12=" ",V12=" ",W12=" ",X12=" ",Y12=" ",Z12=" ",AA12=" ",AB12=" ",AC12=" ",AD12=" ",AE12=" ",AF12=" ",AG12=" "),PROPER(AH12),AH12) -> iki | AI13: =IF(AND(S12=" ",T12=" ",U12=" ",V12=" ",W12=" ",X12=" ",Y12=" ",Z12=" ",AA12=" ",AB12=" ",AC12=" ",AD12=" ",AE12=" ",AF12=" ",AG12=" ",AH12=" "),PROPER(AI12),AI12) | AJ13: =IF(AND(T12=" ",U12=" ",V12=" ",W12=" ",X12=" ",Y12=" ",Z12=" ",AA12=" ",AB12=" ",AC12=" ",AD12=" ",AE12=" ",AF12=" ",AG12=" ",AH12=" ",AI12=" "),PROPER(AJ12),AJ12)
C14: Aylıq ödəniş: | D14: =Annuity!F1 -> 106 | E14: AZN | J14: * Bu hesab üzrə istənilən filialdan ödəmək olar. | P14: =D10-P13 -> 1017.6 | R14: =TRIM(R13&S13&T13&U13&V13&W13&X13&Y13&Z13&AA13&AB13&AC13&AD13&AE13&AF13&AG13&AH13&" manat") -> Bir min iki yüz yetmiş iki manat
C15: Cərimə: | D15: Gecikdirilmiş əsas məbləğə hər gün 1% cərimə hesablanır. | P15: =D10*Data!C86% -> 254.4
C16: Tarix | D16: Ayların sayı | E16: Ödəniş | F16: Əsas borc | G16: Faiz | H16: Qalıq | J16: Beynəlxalq Bank ASC Nərimanov filialı | P16: =Data!C78 -> 12 | R16: =CONCATENATE(R14," ",R15) -> Bir min iki yüz yetmiş iki manat
C17: =Data!E5 -> 45768 | D17: 0 | J17: H/h: AZ42IBAZ40090019442129326206 | P17: =(P14-D10)*(P13%/P11) -> -32.35968
A18: =IF(C17,DATE((YEAR(C17)-1900),MONTH(C17)+1,IF(DAY(C17)>DAY(DATE((YEAR(C17)-1900),MONTH(C17)+2,1)-1),DAY(DATE((YEAR(C17)-1900),MONTH(C17)+2,1)-1),DAY(C$17)))) -> 45798 | B18: =WEEKDAY(A18,2) -> 3 | C18: =IF(D18="-","-",IF(MONTH(IF(B18=6,A18-1,IF(B18=7,A18+1,A18)))=MONTH(C17),A18+2,IF(MONTH(IF(B18=6,A18-1,IF(B18=7,A18+1,A18)))=MONTH(A19),A18-2,IF(B18=6,A18-1,IF(B18=7,A18+1,A18))))) -> 45798 | D18: =IF(D$12>D17,D17+1,"-") -> 1 | E18: =SUM(F18:G18) -> 106 | F18: =Annuity!E8 -> 106 | G18: =Annuity!F8 -> 0 | H18: =D10-F18 -> 1166 | J18: * Bu hesab üzrə istənilən filialdan ödəmək olar.
A19: =IF(A18,DATE((YEAR(A18)-1900),MONTH(A18)+1,IF(DAY(A18)>DAY(DATE((YEAR(A18)-1900),MONTH(A18)+2,1)-1),DAY(DATE((YEAR(A18)-1900),MONTH(A18)+2,1)-1),DAY(C$17)))) -> 45829 | B19: =WEEKDAY(A19,2) -> 6 | C19: =IF(D19="-","-",IF(MONTH(IF(B19=6,A19-1,IF(B19=7,A19+1,A19)))=MONTH(C18),A19+2,IF(MONTH(IF(B19=6,A19-1,IF(B19=7,A19+1,A19)))=MONTH(A20),A19-2,IF(B19=6,A19-1,IF(B19=7,A19+1,A19))))) -> 45828 | D19: =IF(D$12>D18,D18+1,"-") -> 2 | E19: =SUM(F19:G19) -> 106 | F19: =Annuity!E9 -> 106 | G19: =Annuity!F9 -> 0 | H19: =H18-F19 -> 1060 | P19: =(PP!O12-PP!F78)*PP!D11/PP!G78 -> #DIV/0!
A20: =IF(A19,DATE((YEAR(A19)-1900),MONTH(A19)+1,IF(DAY(A19)>DAY(DATE((YEAR(A19)-1900),MONTH(A19)+2,1)-1),DAY(DATE((YEAR(A19)-1900),MONTH(A19)+2,1)-1),DAY(C$17)))) -> 45859 | B20: =WEEKDAY(A20,2) -> 1 | C20: =IF(D20="-","-",IF(MONTH(IF(B20=6,A20-1,IF(B20=7,A20+1,A20)))=MONTH(C19),A20+2,IF(MONTH(IF(B20=6,A20-1,IF(B20=7,A20+1,A20)))=MONTH(A21),A20-2,IF(B20=6,A20-1,IF(B20=7,A20+1,A20))))) -> 45859 | D20: =IF(D$12>D19,D19+1,"-") -> 3 | E20: =SUM(F20:G20) -> 106 | F20: =Annuity!E10 -> 106 | G20: =Annuity!F10 -> 0 | H20: =H19-F20 -> 954 | J20: İDEAL KREDİT -in ünvanı:
A21: =IF(A20,DATE((YEAR(A20)-1900),MONTH(A20)+1,IF(DAY(A20)>DAY(DATE((YEAR(A20)-1900),MONTH(A20)+2,1)-1),DAY(DATE((YEAR(A20)-1900),MONTH(A20)+2,1)-1),DAY(C$17)))) -> 45890 | B21: =WEEKDAY(A21,2) -> 4 | C21: =IF(D21="-","-",IF(MONTH(IF(B21=6,A21-1,IF(B21=7,A21+1,A21)))=MONTH(C20),A21+2,IF(MONTH(IF(B21=6,A21-1,IF(B21=7,A21+1,A21)))=MONTH(A22),A21-2,IF(B21=6,A21-1,IF(B21=7,A21+1,A21))))) -> 45890 | D21: =IF(D$12>D20,D20+1,"-") -> 4 | E21: =SUM(F21:G21) -> 106 | F21: =Annuity!E11 -> 106 | G21: =Annuity!F11 -> 0 | H21: =H20-F21 -> 848 | J21: Bakı şəh, Binəqədi ray, 7-ci MKR,
A22: =IF(A21,DATE((YEAR(A21)-1900),MONTH(A21)+1,IF(DAY(A21)>DAY(DATE((YEAR(A21)-1900),MONTH(A21)+2,1)-1),DAY(DATE((YEAR(A21)-1900),MONTH(A21)+2,1)-1),DAY(C$17)))) -> 45921 | B22: =WEEKDAY(A22,2) -> 7 | C22: =IF(D22="-","-",IF(MONTH(IF(B22=6,A22-1,IF(B22=7,A22+1,A22)))=MONTH(C21),A22+2,IF(MONTH(IF(B22=6,A22-1,IF(B22=7,A22+1,A22)))=MONTH(A23),A22-2,IF(B22=6,A22-1,IF(B22=7,A22+1,A22))))) -> 45922 | D22: =IF(D$12>D21,D21+1,"-") -> 5 | E22: =SUM(F22:G22) -> 106 | F22: =Annuity!E12 -> 106 | G22: =Annuity!F12 -> 0 | H22: =H21-F22 -> 742 | J22: S.S.Axundov küç., 3123-cü məhəllə
A23: =IF(A22,DATE((YEAR(A22)-1900),MONTH(A22)+1,IF(DAY(A22)>DAY(DATE((YEAR(A22)-1900),MONTH(A22)+2,1)-1),DAY(DATE((YEAR(A22)-1900),MONTH(A22)+2,1)-1),DAY(C$17)))) -> 45951 | B23: =WEEKDAY(A23,2) -> 2 | C23: =IF(D23="-","-",IF(MONTH(IF(B23=6,A23-1,IF(B23=7,A23+1,A23)))=MONTH(C22),A23+2,IF(MONTH(IF(B23=6,A23-1,IF(B23=7,A23+1,A23)))=MONTH(A24),A23-2,IF(B23=6,A23-1,IF(B23=7,A23+1,A23))))) -> 45951 | D23: =IF(D$12>D22,D22+1,"-") -> 6 | E23: =SUM(F23:G23) -> 106 | F23: =Annuity!E13 -> 106 | G23: =Annuity!F13 -> 0 | H23: =H22-F23 -> 636 | J23: Tel: 012 526 26 25
A24: =IF(A23,DATE((YEAR(A23)-1900),MONTH(A23)+1,IF(DAY(A23)>DAY(DATE((YEAR(A23)-1900),MONTH(A23)+2,1)-1),DAY(DATE((YEAR(A23)-1900),MONTH(A23)+2,1)-1),DAY(C$17)))) -> 45982 | B24: =WEEKDAY(A24,2) -> 5 | C24: =IF(D24="-","-",IF(MONTH(IF(B24=6,A24-1,IF(B24=7,A24+1,A24)))=MONTH(C23),A24+2,IF(MONTH(IF(B24=6,A24-1,IF(B24=7,A24+1,A24)))=MONTH(A25),A24-2,IF(B24=6,A24-1,IF(B24=7,A24+1,A24))))) -> 45982 | D24: =IF(D$12>D23,D23+1,"-") -> 7 | E24: =SUM(F24:G24) -> 106 | F24: =Annuity!E14 -> 106 | G24: =Annuity!F14 -> 0 | H24: =H23-F24 -> 530
A25: =IF(A24,DATE((YEAR(A24)-1900),MONTH(A24)+1,IF(DAY(A24)>DAY(DATE((YEAR(A24)-1900),MONTH(A24)+2,1)-1),DAY(DATE((YEAR(A24)-1900),MONTH(A24)+2,1)-1),DAY(C$17)))) -> 46012 | B25: =WEEKDAY(A25,2) -> 7 | C25: =IF(D25="-","-",IF(MONTH(IF(B25=6,A25-1,IF(B25=7,A25+1,A25)))=MONTH(C24),A25+2,IF(MONTH(IF(B25=6,A25-1,IF(B25=7,A25+1,A25)))=MONTH(A26),A25-2,IF(B25=6,A25-1,IF(B25=7,A25+1,A25))))) -> 46013 | D25: =IF(D$12>D24,D24+1,"-") -> 8 | E25: =SUM(F25:G25) -> 106 | F25: =Annuity!E15 -> 106 | G25: =Annuity!F15 -> 0 | H25: =H24-F25 -> 424
A26: =IF(A25,DATE((YEAR(A25)-1900),MONTH(A25)+1,IF(DAY(A25)>DAY(DATE((YEAR(A25)-1900),MONTH(A25)+2,1)-1),DAY(DATE((YEAR(A25)-1900),MONTH(A25)+2,1)-1),DAY(C$17)))) -> 46043 | B26: =WEEKDAY(A26,2) -> 3 | C26: =IF(D26="-","-",IF(MONTH(IF(B26=6,A26-1,IF(B26=7,A26+1,A26)))=MONTH(C25),A26+2,IF(MONTH(IF(B26=6,A26-1,IF(B26=7,A26+1,A26)))=MONTH(A27),A26-2,IF(B26=6,A26-1,IF(B26=7,A26+1,A26))))) -> 46043 | D26: =IF(D$12>D25,D25+1,"-") -> 9 | E26: =SUM(F26:G26) -> 106 | F26: =Annuity!E16 -> 106 | G26: =Annuity!F16 -> 0 | H26: =H25-F26 -> 318
A27: =IF(A26,DATE((YEAR(A26)-1900),MONTH(A26)+1,IF(DAY(A26)>DAY(DATE((YEAR(A26)-1900),MONTH(A26)+2,1)-1),DAY(DATE((YEAR(A26)-1900),MONTH(A26)+2,1)-1),DAY(C$17)))) -> 46074 | B27: =WEEKDAY(A27,2) -> 6 | C27: =IF(D27="-","-",IF(MONTH(IF(B27=6,A27-1,IF(B27=7,A27+1,A27)))=MONTH(C26),A27+2,IF(MONTH(IF(B27=6,A27-1,IF(B27=7,A27+1,A27)))=MONTH(A28),A27-2,IF(B27=6,A27-1,IF(B27=7,A27+1,A27))))) -> 46073 | D27: =IF(D$12>D26,D26+1,"-") -> 10 | E27: =SUM(F27:G27) -> 106 | F27: =Annuity!E17 -> 106 | G27: =Annuity!F17 -> 0 | H27: =H26-F27 -> 212
A28: =IF(A27,DATE((YEAR(A27)-1900),MONTH(A27)+1,IF(DAY(A27)>DAY(DATE((YEAR(A27)-1900),MONTH(A27)+2,1)-1),DAY(DATE((YEAR(A27)-1900),MONTH(A27)+2,1)-1),DAY(C$17)))) -> 46102 | B28: =WEEKDAY(A28,2) -> 6 | C28: =IF(D28="-","-",IF(MONTH(IF(B28=6,A28-1,IF(B28=7,A28+1,A28)))=MONTH(C27),A28+2,IF(MONTH(IF(B28=6,A28-1,IF(B28=7,A28+1,A28)))=MONTH(A29),A28-2,IF(B28=6,A28-1,IF(B28=7,A28+1,A28))))) -> 46101 | D28: =IF(D$12>D27,D27+1,"-") -> 11 | E28: =SUM(F28:G28) -> 106 | F28: =Annuity!E18 -> 106 | G28: =Annuity!F18 -> 0 | H28: =H27-F28 -> 106
A29: =IF(A28,DATE((YEAR(A28)-1900),MONTH(A28)+1,IF(DAY(A28)>DAY(DATE((YEAR(A28)-1900),MONTH(A28)+2,1)-1),DAY(DATE((YEAR(A28)-1900),MONTH(A28)+2,1)-1),DAY(C$17)))) -> 46133 | B29: =WEEKDAY(A29,2) -> 2 | C29: =IF(D29="-","-",IF(MONTH(IF(B29=6,A29-1,IF(B29=7,A29+1,A29)))=MONTH(C28),A29+2,IF(MONTH(IF(B29=6,A29-1,IF(B29=7,A29+1,A29)))=MONTH(A30),A29-2,IF(B29=6,A29-1,IF(B29=7,A29+1,A29))))) -> 46133 | D29: =IF(D$12>D28,D28+1,"-") -> 12 | E29: =SUM(F29:G29) -> 106 | F29: =Annuity!E19 -> 106 | G29: =Annuity!F19 -> 0 | H29: =H28-F29 -> 0
A30: =IF(A29,DATE((YEAR(A29)-1900),MONTH(A29)+1,IF(DAY(A29)>DAY(DATE((YEAR(A29)-1900),MONTH(A29)+2,1)-1),DAY(DATE((YEAR(A29)-1900),MONTH(A29)+2,1)-1),DAY(C$17)))) -> 46163 | B30: =WEEKDAY(A30,2) -> 4 | C30: =IF(D30="-","-",IF(MONTH(IF(B30=6,A30-1,IF(B30=7,A30+1,A30)))=MONTH(C29),A30+2,IF(MONTH(IF(B30=6,A30-1,IF(B30=7,A30+1,A30)))=MONTH(A31),A30-2,IF(B30=6,A30-1,IF(B30=7,A30+1,A30))))) -> - | D30: =IF(D$12>D29,D29+1,"-") -> - | E30: =SUM(F30:G30) -> 0 | F30: =Annuity!E20 -> 0 | G30: =Annuity!F20 -> 0 | H30: =H29-F30 -> 0
A31: =IF(A30,DATE((YEAR(A30)-1900),MONTH(A30)+1,IF(DAY(A30)>DAY(DATE((YEAR(A30)-1900),MONTH(A30)+2,1)-1),DAY(DATE((YEAR(A30)-1900),MONTH(A30)+2,1)-1),DAY(C$17)))) -> 46194 | B31: =WEEKDAY(A31,2) -> 7 | C31: =IF(D31="-","-",IF(MONTH(IF(B31=6,A31-1,IF(B31=7,A31+1,A31)))=MONTH(C30),A31+2,IF(MONTH(IF(B31=6,A31-1,IF(B31=7,A31+1,A31)))=MONTH(A32),A31-2,IF(B31=6,A31-1,IF(B31=7,A31+1,A31))))) -> - | D31: =IF(D$12>D30,D30+1,"-") -> - | E31: =SUM(F31:G31) -> 0 | F31: =Annuity!E21 -> 0 | G31: =Annuity!F21 -> 0 | H31: =H30-F31 -> 0 | K31: DİQQƏT!
A32: =IF(A31,DATE((YEAR(A31)-1900),MONTH(A31)+1,IF(DAY(A31)>DAY(DATE((YEAR(A31)-1900),MONTH(A31)+2,1)-1),DAY(DATE((YEAR(A31)-1900),MONTH(A31)+2,1)-1),DAY(C$17)))) -> 46224 | B32: =WEEKDAY(A32,2) -> 2 | C32: =IF(D32="-","-",IF(MONTH(IF(B32=6,A32-1,IF(B32=7,A32+1,A32)))=MONTH(C31),A32+2,IF(MONTH(IF(B32=6,A32-1,IF(B32=7,A32+1,A32)))=MONTH(A33),A32-2,IF(B32=6,A32-1,IF(B32=7,A32+1,A32))))) -> - | D32: =IF(D$12>D31,D31+1,"-") -> - | E32: =SUM(F32:G32) -> 0 | F32: =Annuity!E22 -> 0 | G32: =Annuity!F22 -> 0 | H32: =H31-F32 -> 0 | J32: HÖRMƏTLİ MÜŞTƏRİ!
A33: =IF(A32,DATE((YEAR(A32)-1900),MONTH(A32)+1,IF(DAY(A32)>DAY(DATE((YEAR(A32)-1900),MONTH(A32)+2,1)-1),DAY(DATE((YEAR(A32)-1900),MONTH(A32)+2,1)-1),DAY(C$17)))) -> 46255 | B33: =WEEKDAY(A33,2) -> 5 | C33: =IF(D33="-","-",IF(MONTH(IF(B33=6,A33-1,IF(B33=7,A33+1,A33)))=MONTH(C32),A33+2,IF(MONTH(IF(B33=6,A33-1,IF(B33=7,A33+1,A33)))=MONTH(A34),A33-2,IF(B33=6,A33-1,IF(B33=7,A33+1,A33))))) -> - | D33: =IF(D$12>D32,D32+1,"-") -> - | E33: =SUM(F33:G33) -> 0 | F33: =Annuity!E23 -> 0 | G33: =Annuity!F23 -> 0 | H33: =H32-F33 -> 0 | J33: KREDİT ÖDƏNİŞİNİZİ ÖDƏNİŞ QRAFİKİNDƏ
A34: =IF(A33,DATE((YEAR(A33)-1900),MONTH(A33)+1,IF(DAY(A33)>DAY(DATE((YEAR(A33)-1900),MONTH(A33)+2,1)-1),DAY(DATE((YEAR(A33)-1900),MONTH(A33)+2,1)-1),DAY(C$17)))) -> 46286 | B34: =WEEKDAY(A34,2) -> 1 | C34: =IF(D34="-","-",IF(MONTH(IF(B34=6,A34-1,IF(B34=7,A34+1,A34)))=MONTH(C33),A34+2,IF(MONTH(IF(B34=6,A34-1,IF(B34=7,A34+1,A34)))=MONTH(A35),A34-2,IF(B34=6,A34-1,IF(B34=7,A34+1,A34))))) -> - | D34: =IF(D$12>D33,D33+1,"-") -> - | E34: =SUM(F34:G34) -> 0 | F34: =Annuity!E24 -> 0 | G34: =Annuity!F24 -> 0 | H34: =H33-F34 -> 0 | J34: NƏZƏRDƏ TUTULAN TARİXLƏRDƏ SAAT
A35: =IF(A34,DATE((YEAR(A34)-1900),MONTH(A34)+1,IF(DAY(A34)>DAY(DATE((YEAR(A34)-1900),MONTH(A34)+2,1)-1),DAY(DATE((YEAR(A34)-1900),MONTH(A34)+2,1)-1),DAY(C$17)))) -> 46316 | B35: =WEEKDAY(A35,2) -> 3 | C35: =IF(D35="-","-",IF(MONTH(IF(B35=6,A35-1,IF(B35=7,A35+1,A35)))=MONTH(C34),A35+2,IF(MONTH(IF(B35=6,A35-1,IF(B35=7,A35+1,A35)))=MONTH(A36),A35-2,IF(B35=6,A35-1,IF(B35=7,A35+1,A35))))) -> - | D35: =IF(D$12>D34,D34+1,"-") -> - | E35: =SUM(F35:G35) -> 0 | F35: =Annuity!E25 -> 0 | G35: =Annuity!F25 -> 0 | H35: =H34-F35 -> 0 | J35: 16:30 -DƏK ÖDƏMƏLİSİNİZ. ƏKS HALDA
A36: =IF(A35,DATE((YEAR(A35)-1900),MONTH(A35)+1,IF(DAY(A35)>DAY(DATE((YEAR(A35)-1900),MONTH(A35)+2,1)-1),DAY(DATE((YEAR(A35)-1900),MONTH(A35)+2,1)-1),DAY(C$17)))) -> 46347 | B36: =WEEKDAY(A36,2) -> 6 | C36: =IF(D36="-","-",IF(MONTH(IF(B36=6,A36-1,IF(B36=7,A36+1,A36)))=MONTH(C35),A36+2,IF(MONTH(IF(B36=6,A36-1,IF(B36=7,A36+1,A36)))=MONTH(A37),A36-2,IF(B36=6,A36-1,IF(B36=7,A36+1,A36))))) -> - | D36: =IF(D$12>D35,D35+1,"-") -> - | E36: =SUM(F36:G36) -> 0 | F36: =Annuity!E26 -> 0 | G36: =Annuity!F26 -> 0 | H36: =H35-F36 -> 0 | J36: KREDİTİNİZ GECİKMƏDƏ QALACAQ.
A37: =IF(A36,DATE((YEAR(A36)-1900),MONTH(A36)+1,IF(DAY(A36)>DAY(DATE((YEAR(A36)-1900),MONTH(A36)+2,1)-1),DAY(DATE((YEAR(A36)-1900),MONTH(A36)+2,1)-1),DAY(C$17)))) -> 46377 | B37: =WEEKDAY(A37,2) -> 1 | C37: =IF(D37="-","-",IF(MONTH(IF(B37=6,A37-1,IF(B37=7,A37+1,A37)))=MONTH(C36),A37+2,IF(MONTH(IF(B37=6,A37-1,IF(B37=7,A37+1,A37)))=MONTH(A38),A37-2,IF(B37=6,A37-1,IF(B37=7,A37+1,A37))))) -> - | D37: =IF(D$12>D36,D36+1,"-") -> - | E37: =SUM(F37:G37) -> 0 | F37: =Annuity!E27 -> 0 | G37: =Annuity!F27 -> 0 | H37: =H36-F37 -> 0
A38: =IF(A37,DATE((YEAR(A37)-1900),MONTH(A37)+1,IF(DAY(A37)>DAY(DATE((YEAR(A37)-1900),MONTH(A37)+2,1)-1),DAY(DATE((YEAR(A37)-1900),MONTH(A37)+2,1)-1),DAY(C$17)))) -> 46408 | B38: =WEEKDAY(A38,2) -> 4 | C38: =IF(D38="-","-",IF(MONTH(IF(B38=6,A38-1,IF(B38=7,A38+1,A38)))=MONTH(C37),A38+2,IF(MONTH(IF(B38=6,A38-1,IF(B38=7,A38+1,A38)))=MONTH(A39),A38-2,IF(B38=6,A38-1,IF(B38=7,A38+1,A38))))) -> - | D38: =IF(D$12>D37,D37+1,"-") -> - | E38: =SUM(F38:G38) -> 0 | F38: =Annuity!E28 -> 0 | G38: =Annuity!F28 -> 0 | H38: =H37-F38 -> 0 | J38: Onlayn ödəniş üçün QR Kodu scan edin
A39: =IF(A38,DATE((YEAR(A38)-1900),MONTH(A38)+1,IF(DAY(A38)>DAY(DATE((YEAR(A38)-1900),MONTH(A38)+2,1)-1),DAY(DATE((YEAR(A38)-1900),MONTH(A38)+2,1)-1),DAY(C$17)))) -> 46439 | B39: =WEEKDAY(A39,2) -> 7 | C39: =IF(D39="-","-",IF(MONTH(IF(B39=6,A39-1,IF(B39=7,A39+1,A39)))=MONTH(C38),A39+2,IF(MONTH(IF(B39=6,A39-1,IF(B39=7,A39+1,A39)))=MONTH(A40),A39-2,IF(B39=6,A39-1,IF(B39=7,A39+1,A39))))) -> - | D39: =IF(D$12>D38,D38+1,"-") -> - | E39: =SUM(F39:G39) -> 0 | F39: =Annuity!E29 -> 0 | G39: =Annuity!F29 -> 0 | H39: =H38-F39 -> 0
A40: =IF(A39,DATE((YEAR(A39)-1900),MONTH(A39)+1,IF(DAY(A39)>DAY(DATE((YEAR(A39)-1900),MONTH(A39)+2,1)-1),DAY(DATE((YEAR(A39)-1900),MONTH(A39)+2,1)-1),DAY(C$17)))) -> 46467 | B40: =WEEKDAY(A40,2) -> 7 | C40: =IF(D40="-","-",IF(MONTH(IF(B40=6,A40-1,IF(B40=7,A40+1,A40)))=MONTH(C39),A40+2,IF(MONTH(IF(B40=6,A40-1,IF(B40=7,A40+1,A40)))=MONTH(A41),A40-2,IF(B40=6,A40-1,IF(B40=7,A40+1,A40))))) -> - | D40: =IF(D$12>D39,D39+1,"-") -> - | E40: =SUM(F40:G40) -> 0 | F40: =Annuity!E30 -> 0 | G40: =Annuity!F30 -> 0 | H40: =H39-F40 -> 0
A41: =IF(A40,DATE((YEAR(A40)-1900),MONTH(A40)+1,IF(DAY(A40)>DAY(DATE((YEAR(A40)-1900),MONTH(A40)+2,1)-1),DAY(DATE((YEAR(A40)-1900),MONTH(A40)+2,1)-1),DAY(C$17)))) -> 46498 | B41: =WEEKDAY(A41,2) -> 3 | C41: =IF(D41="-","-",IF(MONTH(IF(B41=6,A41-1,IF(B41=7,A41+1,A41)))=MONTH(C40),A41+2,IF(MONTH(IF(B41=6,A41-1,IF(B41=7,A41+1,A41)))=MONTH(A42),A41-2,IF(B41=6,A41-1,IF(B41=7,A41+1,A41))))) -> - | D41: =IF(D$12>D40,D40+1,"-") -> - | E41: =SUM(F41:G41) -> 0 | F41: =Annuity!E31 -> 0 | G41: =Annuity!F31 -> 0 | H41: =H40-F41 -> 0
...

Sheet KR
B2: "İDEAL KREDİT" BOKT MMC
F3: Əlaqəli Kredit Müqaviləsi № | I3: =Data!I5 -> 04/2078-25
B5: Bakı şəhəri | M5: =Data!E5 -> 45768
B7: Əsasnamə və Etibarnamə əsasında fəaliyyət göstərən (gələcəkdə "BOKT" adlanacaq) BOKT “İDEAL KREDİT” MMC-nin Partnyorluq kreditləri bölməsinin müdiri
B8: Şirməmmədov Vüsal Əlyar oğlu şəxsində bir tərəfdən, gələcəkdə "Borcalan" adlanacaq fiziki şəxs | J8: =Data!C23 -> Yunusov Vüqar Fikrət oğlu | N8: şəxsində
B9: digər tərəfdən,(birlikdə "Tərəflər" adlanacaq) aşağıdakılar barədə razılığa gələrək bu müqaviləni bağladılar.
B10: 1.MÜQAVİLƏNİN PREDMETİ
B11: 1.1. Bu Müqavilə “BOKT” tərəfindən “Borcalan”a kreditin verilməsi və kreditin qaytarılması şərtləri çərçivəsində Tərəflərin hüquq və öhdəliklərini tənzimləyir.
B12: 1.2. Bu müqavilə üzrə "BOKT" "Borcalan"a | F12: =Data!C94 -> Fərəcov Elsevər Ələmdar oğlu | I12: (bundan sonra "Partnyor") tərəfindən satışı həyata keçirilən
B13: =Data!C68 -> İstehlak mal(lar)ının alınması üçün | E13: =Data!C74 -> 1272 | F13: =PP!AK6 -> (Bir min iki yüz yetmiş iki manat ) | J13: məbləğində istehlak krediti verməyi "Borcalan" isə
B14: aldığı borcu bu Müqavilədə müəyyən edilmiş müddətdə və qaydada, ödəniş qrafiki (Əlavə №1) əsasında "BOKT"-a qaytarmağı öz öhdəsinə götürür.
B15: 1.3. Bu müqaviləyə əsasən alınmış istehlak malları (bundan sonra "Girov Predmeti") "Borcalan"ın razılığı ilə "BOKT"nin xeyrinə girov qoyulur. "Girov Predmeti"
B16: Borcalanda qalır. "Borcalan" "BOKT" tərəfndən "Girov Predmeti"nin Daşınar Əmlakın Yüklülüyünün Dövlət Reyestrində (DƏYDR) qeydiyyatının aparılmasına və bu
B17: müqavilə üzrə öhdəliyin vaxtının bitmə müddətindən əlavə 3 (üç) il müddətində yüklü (girovda) olaraq qalmasına razılıq verir.
B18: 1.4. Kreditin verilməsi | D18: =Data!E53 -> 0 | F18: №-li nömrəli plastik ödəniş kartına və ya partnyorun bank hesabına köçürmə yolu ilə həyata keçirilir.
B19: 1.5. Kredit rəsmiləşdirilməsinə görə ümumi kredit məbləğinin | G19: =Data!C86/100 -> 0.2 | H19: həcmində komissiya haqqı və “Borcalan”a təqdim edilən ödəniş kartına görə | N19: =Data!C88 -> 0
B20: kart xərci köçürülmə zamanı tutulur.
B21: 1.6. Kredit "Borcalan"a kreditdən istifadə haqqı olaraq illik | G21: =Data!C76 -> 0 | H21: % (annuitet qaydasında) hesablanmaqla | K21: =Data!C78 -> 12 | L21: ay müddətinə verilir.
B22: 1.7. Bu Müqaviləyə əsasən alınmış mal(lar)ın ümumi dəyəri | G22: =Data!C84 -> 1672 | H22: ='Formula 1'!BA4 -> (Bir min altı yüz yetmiş iki manat ) | M22: təşkil edir.
B23: 1.8. Borcalan kredit müqaviləsi üzrə borcun ödənilməsini ödəniş qrafikinə (Əlavə №1) uyğun olaraq həyata keçirir. Borcalan kredit borcunu ödəniş qrafikində
B24: (Əlavə №1) nəzərdə tutulmuş tarixlərdə ödəmədikdə hər gecikdirilmiş gün üçün aylıq ödəniləcək borc məbləğinin 1%-i həcmində dəbbə (cərimə) pulu ödəyir.
B25: 1.9. Bu Müqaviləyə və onun əlavələrinə uyğun olaraq ödəniş məbləğləri "BOKT"nin hər hansı bir əməkdaşına deyil, yalnız onun bank hesablarına və digər ödəmə
B26: vasitələrinə(ödəniş terminalları, onlayn ödənişlər) ödənilir.
B27: 2.TƏRƏFLƏRİN HÜQUQ VƏ VƏZİFƏLƏRİ
B28: 2.1. "BOKT"nın hüquqları:
B29: 2.1.1. "Borcalan" bu Müqaviləyə və onun əlavə(lər)sinə uyğun olaraq ödəniş qrafikində nəzərdə tutulmuş ödəniş məbləğlərini ödəmədikdə/vaxında ödəmədikdə
B30: (həmçinin "Borcalan"ın əmlak və ya maliyyə vəziyyətinin pisləşməsi səbəbindən ödəmədikdə) kreditin vaxtından əvvəl tam ödənilməsini "Borcalan"dan tələb etmək;
B31: 2.1.2. "Borcalan" bu Müqaviləyə və onun əlavə(lər)sinə uyğun olaraq ödəniş məbləğlərini bu Müqavilənin 1.10-cu bəndində göstərilmiş qaydada bank hesabları və
B32: digər ödəmə vasitələri (kassa, ödəniş terminalları, onlayn ödənişlər) ilə deyil, "BOKT"nin hər hansı bir əməkdaşına ödəməsini bildirdikdə və ya bu cür ödənişlərin
B33: edilməsi ilə bağlı hər hansı bir qəbz forması təqdim etdikdə, həmin ödənişləri və ya qəbzləri qəbul etmədən ödənişlərin bu müqavilənin 1.10-cu bəndində göstərilən
B34: qaydada yenidən ödənilməsini tələb etmək;
... B85: 4.2.2. “Borcalan” tərəfindən kreditlə əlaqədar “BOKT”nı aldatmağa yönəlmiş və ya qanunvericiliyə zidd hər hansı bir hərəkətin edilməsi və ya yanlış məlumatların və
B89: BOKT | H89: Borcalan
B91: ya sənədlərin təqdim edilməsi barədə “BOKT”da ciddi şübhələr və ya məlumat olduqda;
B92: 4.2.3. Bu müqavilə üzrə “Borcalan”ın öhdəliklərini yerinə yetirməsinə mənfi təsir göstərə biləcək hallar barədə məlumat daxil olduqda.
B93: 4.3. «BOKT» «Borcalan»ı 1 (bir) ay əvvəlcədən yazılı xəbərdar etməklə aşağıdakı hallarda bu Müqaviləni birtərəfli qaydada ləğv edə və kreditin (əsas məbləğ,
B94: hesablanmış faizlər, cərimə və s.) vaxtından əvvəl qaytarılmasını tələb edə bilər:
B95: 4.3.1. “Borcalan” kredit müqaviləsi üzrə öhdəliklərini (əsas borc və ya faizləri, yaxud onların bir hissəsini) bu müqavilənin ayrılmaz tərkib hissəsi olan “Ödəniş qrafiki
B96: (Əlavə №1)" üzrə ödənişləri yerinə yetirmədikdə;
B97: 4.3.2. “Borcalan” kreditdən təyinatına uyğun istifadə etmədikdə;
...

Sheet M-Forması
B1: İSTEHLAK KREDİTİ MÜQAVİLƏSİ ÜZRƏ STANDART MƏLUMATLANDIRMA FORMASI
B4: 1 | C4: Borcverənin adı | D4: Bank Olmayan Kredit Təşkilatı "İDEAL KREDİT" Məhdud Məsuliyyətli Cəmiyyəti
B5: 2 | C5: Borcverənin ünvanı | D5: Bakı ş, Binəqədi r, 7 MKR, S.S.Axundov küç, 3123-cü məh.
B6: 3 | C6: Kreditin növü | D6: İstehlak krediti
B7: 4 | C7: Kreditin məbləği (kredit xəttinin limiti) və valyutası | D7: =Data!C74 -> 1272
B8: 5 | C8: Kreditin qaytarılma müddəti | D8: Siz krediti | E8: =D110 -> 46133 | F8: il tarixindən gec olmayaraq qaytarmalısınız.
B10: 6 | C10: Kreditin ödəniş şərtləri | D10: Kredit ödənişlərini aşağıdakı üsullarla həyata keçirə bilərsiniz:
D11: ● "İDEAL KREDİT"-in Azərpoçt MMC PF1, Kapital Bank ASC Kob mərkəzi filialı və ya “Beynəlxalq Bank” ASC Nərimanov filialında olan bank hesablarından ödəməklə;
D12: ● E-Manat, MilliÖn ödəniş terminalları ilə ödəməklə;
D13: ● Nağd qaydada BOKT-nin kassasına ödəməklə;
D14: ● https://hesab.az/ onlayn ödəniş sistemi vasitəsilə ödəməklə.
D15: Qeyd edilən üsullardan hər hansı birinin istifadəsinin mümkün olmaması Sizi digər mümkün üsullardan istifadə etməklə ödənişləri vaxtında həyata keçirmək öhdəliyindən azad etmir.
B16: 7 | C16: Kreditlə alınacaq mal(lar)ın və ya xidmət(lər)in Adı | D16: =Data!C92 -> Monitor,kamera,Ambians , Led
C18: Nağd qiyməti (malın və ya xidmətin alınması zamanı birdəfəlik ödəniş edildikdə) | D18: =KR!G22 -> 1672 | E18: ='Formula 1'!BA4 -> (Bir min altı yüz yetmiş iki manat )
B25: 8 | C25: Kredit üzrə tətbiq edilən faizlərin illik dərəcəsi və (və ya) digər ödənişlərin məbləği və onların tətbiq edilmə şərtləri | D25: =C102 -> ● illik faiz dərəcəsi - 0%
D26: ● bu Formanın 6-cı hissəsində göstərilən ödəniş üsullarının(borcverənə məxsus ödəniş şəbəkəsindən istifadə edildikdə) tətbiqi ilə bağlı komisyon haqlar 0%
D27: ● digər ödənişlər - yoxdur
D28: ● istehlak kreditinin rəsmiləşdirilməsinə görə ümumi kredit məbləğinin - həcmində komissiya haqqı
B29: 9 | C29: Faktiki illik faiz dərəcəsi (FİFD) | D29: Faktiki illik faiz dərəcəsi: | F29: =D109/100 -> 0.435
C31: FİFD kreditin əldə edilməsinə çəkilən xərci göstərir. Bu göstərici vasitəsilə Siz digər kredit təşkilatlarının təkliflərini müqayisə edərək qiymətləndirə bilərsiniz. FİFD Mərkəzi Bankın normativ xarakterli aktında müəyyən edilmiş düstur əsasında hesablanmışdır.
B32: 10 | C32: Tətbiq edildikdə, kredit üzrə faizlərin tutulmadığı müddət barədə aydın və dəqiq məlumat | D32: Tətbiq edilmir
B33: 11 | C33: İstehlakçı tərəfindən edilməli olan ödənişlərin məbləği, sayı və dövriliyi | D33: Tərəfinizdən ödəniləcək ümumi məbləğ:
D34: ● Əsas borc | E34: =Data!C74 -> 1272
D35: ● Faiz borcu | E35: =PP!G78 -> 0
D36: ● Kreditlə əlaqəli digər ödənişlər | G36: =Data!C88 -> 0 | H36: kart xərci
D37: Ödənişlər aşağıdakı cədvəl üzrə həyata keçirilir:
B38: 12 | C38: Yetərli miqdarda olmayan və ya artıq miqdarda edilən ödənişlərin öhdəliyin icrasından silinmə ardıcıllığı | D38: Yetərli miqdarda olmayan ödənişlərin öhdəliyin icrasından silinmə ardıcıllığı: 1-Cərimə borcundan; 2-Faiz borcundan; 3-Əsas borcdan
D40: Artıq miqdarda edilən ödənişlərin öhdəliyin icrasından silinmə ardıcıllığı: - Əsas borcdan
B42: 13 | C42: Tətbiq edildikdə, ödəniş və nağdlaşdırma əməliyyatlarının qeydiyyatını aparan bir və ya bir neçə hesabın saxlanma xərcləri, o cümlədən ödəniş və nağdlaşdırma əməliyyatları üçün ödəniş vasitələrindən istifadə xərcləri, kredit müqaviləsindən irəli gələn digər xərclər və bu xərclərin dəyişdirilmə şərtləri | D42: ● hesabın saxlanma xərcləri - Yoxdur
D43: ● konvertasiya haqqı - Yoxdur
D44: ● nağdlaşdırma komissiyası: a) kredit plastik ödəniş kartı ilə verildilikdə nağdlaşdırma komissiyası bank tariflərinə uyğun olaraq tutulur. b) kredit məbləği əlaqəli kredit müqaviləsi üzrə bank hesabına köçürüldükdə nağdlaşdırma komissiyası tətbiq edilmir.
D45: ● ölkədaxili köçürmələr üzrə komissiyalar - Yoxdur
D46: ● ölkəxarici köçürmələr üzrə komissiyalar - Yoxdur
D47: ● kredit kartı üzrə xərclər - Yoxdur
D48: ● kredit üzrə digər xərclərin adı və məbləği - Yoxdur
D49: ● xərclərin dəyişdirilmə şərtləri (yalnız azaldılma istiqamətində)
B50: 14 | C50: Tətbiq edildikdə, kredit müqaviləsinin bağlanılması ilə bağlı istehlakçı tərəfindən ödənilməli olan notarial xərclərin mövcudluğu | D50: Yoxdur
B51: 15 | C51: Kreditin alınması üçün əlavə xidmət müqaviləsinin, o cümlədən sığorta müqaviləsinin bağlanılması məcburi olduğu hallarda belə müqavilənin növü və istehlakçının istehlak krediti müqaviləsi ilə bağlı belə müqaviləni bağlamaq vəzifəsi | D51: =E104 -> Yoxdur
B52: 16 | C52: İstehlakçının ödənişlərini vaxtında etməməsinin hüquqi nəticələri | D52: Ödənişlər gecikdirildiyi halda bu Formada nəzərdə tutulan gecikdirmə faizləri və ya dəbbə pulu tətbiq edilə, təminata tutma yönəldilə, kreditin vaxtından əvvəl qaytarılması tələb edilə, habelə qanunda və müqavilədə müəyyən edilmiş digər tədbirlər görülə bilər.
B53: 17 | C53: Tətbiq edildikdə, gecikdirilmiş ödənişlərlə bağlı gecikdirilmə faizləri | D53: Gecikən kreditə görə Cərimə (dəbbə) məbləği tutulduğu üçün gecikdirilmə faizi tətbiq edilmir.
...

Sheet Kredit sifarişi
T2: "İDEAL KREDİT" BOKT MMC
T3: KREDİT SİFARİŞİ
B4: Sifarişçi haqqında məlumat
B6: 1. Adı, S.A., A.A. | W6: =Data!C23 -> Yunusov Vüqar Fikrət oğlu
B7: 2. Şəxsiyyət vəsiqəsinin seriyası | V7: =Data!C21 -> AA5512135
B8: 3. Şəxsiyyət vəsiqəsinin verilmə tarixi | W8: =Data!E21 -> 29.10.2023 | AC8: ci il.
B9: 4. Kim tərəfindən verilib | W9: =Data!C27 -> Asan4
B10: 5. Doğum yeri | I10: =Data!C35 -> Azərbaycan | S10: Respublikası | Y10: =Data!D35 -> Bakı | AL10: Vətəndaşlığı | AO10: =Data!C37 -> Azərbaycanlı
B11: 6. Daimi qeydiyyat ünvanı | N11: =Data!C29 -> NEFTÇALA RAYONU, XOL QARABUCAQ Ə/D, DÖRDLƏR KƏNDİ
B12: 7. Faktiki yaşadığı ünvan | N12: =Data!C31 -> Sabunçu ray., Kürdəxanı qəs,Elton İsgəndərov küç,23-cü məhəllə, (113 nömrəli məktəb tərəf)
B13: 8. Əlaqə telefonları
C14: =Data!C33 -> 0703732363 müştəri,
B16: 9. Ailə vəziyyəti | W16: =Data!C39 -> Evli
B17: 10. Uşaqlarının sayı və təvəllüdü | R17: =Data!C59 -> 2
B18: 11. Təhsili | L18: =Data!C41 -> Orta
B19: 12. İşlədiyi yerin adı | K19: =Data!C43 -> Fərdi gəlirlər
B20: 13. İşlədiyi yerin ünvanı | M20: =Data!C45 -> Bakı
B21: 14. Vəzifəsi və iş stajı | L21: =Data!C47 -> Diş texniki
B22: 15. Aylıq əmək haqqı məbləği (manatla) | X22: =Data!C49 -> 1500 | AL22: man
B23: 16. Digər gəlirlər | T23: =Data!C51 -> 0 | AC23: man
B24: 17. Ailə gəlirləri | T24: =Data!C53 -> 500 | AC24: man
B26: ZAMİN 1
B27: 18. Borcun alınmasına təminatçı olan digər şəxs (əgər varsa) onun haqqında qısa məlumat
B28: Adı, S.A., A.A. | K28: =Data!C106 -> 0
B29: Şəxsiyyət vəsiqəsinin seriyası | T29: =Data!C102 -> 0
B30: Şəxsiyyət vəsiqəsinin verilmə tarixi | W30: =Data!E102 -> 0
B31: Kim tərəfindən verilib | V31: =Data!C104 -> ASAN 2
B32: Doğum yeri | AF32: Vətəndaşlığı
B33: Daimi qeydiyyat ünvanı | M33: =Data!C110 -> 0
B34: Faktiki yaşadığı ünvan | M34: =Data!C112 -> 0
B35: Əlaqə telefonları | J35: =Data!C114 -> 0
B36: İşlədiyi yerin adı və vəzifəsi
B37: İşlədiyi yerin ünvanı
B39: ZAMİN 2
B40: 19. Borcun alınmasına təminatçı olan digər şəxs (əgər varsa) onun haqqında qısa məlumat
B41: Adı, S.A., A.A. | K41: =Data!C124 -> 0
B42: Şəxsiyyət vəsiqəsinin seriyası | T42: =Data!C120 -> 0
B43: Şəxsiyyət vəsiqəsinin verilmə tarixi | W43: =Data!E120 -> 0
B44: Kim tərəfindən verilib | V44: =Data!C122 -> 0
B45: Doğum yeri | AF45: Vətəndaşlığı
...

Sheet ZAMIN 1
B2: "İDEAL KREDİT" BOKT MMC
E3: ZAMİNLİK MÜQAVİLƏSİ № | I3: =Data!I5 -> 04/2078-25
C5: Bakı şəhəri | L5: =Data!E5 -> 45768
B7: Əsasnamə və Etibarnamə əsasında fəaliyyət göstərən (gələcəkdə "BOKT" adlanacaq) BOKT “İDEAL KREDİT” MMC-nin Partnyorluq kreditləri bölməsinin
B8: müdiri Şirməmmədov Vüsal Əlyar oğlu şəxsində bir tərəfdən, gələcəkdə "Borcalan" adlanacaq fiziki şəxs | K8: =Data!C23 -> Yunusov Vüqar Fikrət oğlu
B9: digər tərəfdən və gələcəkdə Zamin adlanacaq fiziki şəxs | G9: =Data!C106 -> 0 | K9: üçüncü tərəfdən,(birlikdə Tərəflər
B10: adlanacaq) aşağıdakılar barədə razılığa gələrək bu müqaviləni bağladılar.
B12: 1.MÜQAVİLƏNİN PREDMETİ
B13: 1.1. BOKT ilə Borcalan | D13: =Data!C23 -> Yunusov Vüqar Fikrət oğlu | H13: arasında | I13: =Data!E5 -> 45768 | K13: ci il tarixdə Bakı şəhərində bağlanmış
B14: =Data!I5 -> 04/2078-25 | C14: saylı əlaqəli kredit müqaviləsinə əsasən BOKT Borcalana | H14: =Data!C78 -> 12 | I14: aya qaytarmaq şərti ilə,illik | K14: =Data!C76 -> 0 | L14: % olmaqla | M14: =Data!C74 -> 1272
B15: =PP!AK6 -> (Bir min iki yüz yetmiş iki manat ) | G15: məbləğində kredit vemişdir.
B16: 1.2. Bu müqavilə üzrə "Zamin" | E16: =Data!C106 -> 0 | I16: özünə məxsus bütün daşınar və daşınmaz əmlakları ilə BOKT-la
B17: Borcalan arasında bağlanmış | E17: =Data!E5 -> 45768 | G17: il tarixli, | H17: =Data!I5 -> 04/2078-25 | I17: saylı kredit müqaviləsi üzrə Borcalanın BOKT qarşısında öhdəliklərini
B18: icra etməsi üçün məsuliyyəti öz üzərinə götürürür.
B19: 1.3. Borcalan zaminliklə təmin edilmiş öhdəliyi icra etmədikdə və ya lazımınca icra etmədikdə Zamin və Borcalan BOKT qarşısında birgə məsuliyyət daşıyır.
B20: 1.4. Borcalanın BOKT qarşısındakı öhdəlikləri icra etməməsi və ya lazımınca icra etməməsi nəticəsində BOKT-a dəyən bütün zərərlərin (kredit müqaviləsi
B21: üzrə borcun, dəbbə (cərimə) pulu, məhkəmə xərcləri və s.) əvəzinin ödənilməsi də daxil olmaqla, "İDEAL KREDİT" BOKT qarşısında Borcalan ilə eyni həcmdə,
B22: yəni tam öhdəlik üzrə məsuliyyət daşıyır.
B23: 1.5. Bu müqavilə üzrə zaminlik | E23: =Data!I5 -> 04/2078-25 | F23: saylı kredit müqaviləsinin müddəti bitdiyi tarixdən əlavə 3 il müddətinə qüvvədədir.
B25: 2.TƏRƏFLƏRİN HÜQUQ VƏ VƏZİFƏLƏRİ
B26: 2.1. BOKT-nın hüquq və vəzifələri:
B27: 2.1.1. Borcalan BOKT qarşısında öz öhdəliklərinin icrasını lazımı səviyyədə təmin etmədikdə, BOKT Zamindən verilmiş kreditin və ona hesablanmış faiz
B28: borcunun vaxtından əvvəl qaytarılmasını tələb edə bilər.
B29: 2.1.2. Zamin Borcalanın BOKT qarşısında öhdəliklərinin icrasını təmin etdikdən sonra onun yazılı müraciəti əsasında, BOKT Borcalana qarşı tələbini təsdiq
B30: edən sənədləri Zaminə təqdim etməyə və həmin tələbi təmin edən hüquqları verməyə borcludur.
B31: 2.2. Zaminin hüquq və vəzifələri:
B32: 2.2.1. Zamin Borcalanın əvəzindən onun BOKT qarşısında olan öhdəliklərini icra etdikdən sonra, BOKT-dan Borcalana qarşı tələbini təsdiq edən sənədlərin
B33: (reqres tələblə əlaqədar) və həmin tələbi təmin edən hüquqların ona verilməsini tələb edə bilər.
B34: 2.2.2. Borcalanın əvəzindən onun BOKT-a olan öhdəliyini tam şəkildə icra etdikdən sonra BOKT-nın Borcalana qarşı həmin öhdəlik üzrə hüquqlarından tam
B35: istifadə edə bilər və s.
B36: 2.2.3. Zamin BOKT-nın tələbini ödədikdə bu barədə Borcalanı xəbərdar etməyə borcludur.
... B68: 4.TƏRƏFLƏRİN REKVİZİTLƏRİ:
B69: BOKT | K69: Borcalan
B70: "İDEAL KREDİT" BOKT MMC-nin Partnyorluq kreditləri bölməsi | I70: =Data!C23 -> Yunusov Vüqar Fikrət oğlu
B71: Müdir: Şirməmmədov Vüsal Əlyar oğlu | H71: Ünvan | I71: =Data!C29 -> NEFTÇALA RAYONU, XOL QARABUCAQ Ə/D, DÖRDLƏR KƏNDİ
B72: Hüquqi ünvan: Bakı şəhəri, F.Xoyski küç. 111"A", m.26 | H72: Ş/V № | J72: =Data!C21 -> AA5512135
B73: Faktiki ünvan: Bakı ş, Binəqədi r, 7 MKR, S.S.Axundov küç, 3123-cü məh. | H73: Verilmə tarixi | J73: =Data!E21 -> 29.10.2023 | M73: =Data!C27 -> Asan4
B74: Tel: 012 526 26 25
B75: VÖEN: | C75: 1300480591
I77: Borcalan
...

Sheet ZAMIN 2
B2: "İDEAL KREDİT" BOKT MMC
E3: ZAMİNLİK MÜQAVİLƏSİ № | I3: =Data!I5 -> 04/2078-25
C5: Bakı şəhəri | L5: =Data!E5 -> 45768
B7: Əsasnamə və Etibarnamə əsasında fəaliyyət göstərən (gələcəkdə "BOKT" adlanacaq) BOKT “İDEAL KREDİT” MMC-nin Partnyorluq kreditləri bölməsinin
B8: müdiri Şirməmmədov Vüsal Əlyar oğlu şəxsində bir tərəfdən, gələcəkdə "Borcalan" adlanacaq fiziki şəxs | K8: =Data!C23 -> Yunusov Vüqar Fikrət oğlu
B9: digər tərəfdən və gələcəkdə Zamin adlanacaq fiziki şəxs | G9: =Data!C124 -> 0 | K9: üçüncü tərəfdən,(birlikdə Tərəflər
B10: adlanacaq) aşağıdakılar barədə razılığa gələrək bu müqaviləni bağladılar.
B12: 1.MÜQAVİLƏNİN PREDMETİ
B13: 1.1. BOKT ilə Borcalan | D13: =Data!C23 -> Yunusov Vüqar Fikrət oğlu | H13: arasında | I13: =Data!E5 -> 45768 | K13: ci il tarixdə Bakı şəhərində bağlanmış
B14: =Data!I5 -> 04/2078-25 | C14: saylı əlaqəli kredit müqaviləsinə əsasən BOKT Borcalana | H14: =Data!C78 -> 12 | I14: aya qaytarmaq şərti ilə illik | K14: =Data!C76 -> 0 | L14: % olmaqla | M14: =Data!C74 -> 1272
B15: =PP!AK6 -> (Bir min iki yüz yetmiş iki manat ) | G15: məbləğində kredit vemişdir.
B16: 1.2. Bu müqavilə üzrə "Zamin" | E16: =Data!C124 -> 0 | I16: özünə məxsus bütün daşınar və daşınmaz əmlakları ilə BOKT-la
B17: Borcalan arasında bağlanmış | E17: =Data!E5 -> 45768 | G17: il tarixli, | H17: =Data!I5 -> 04/2078-25 | I17: saylı kredit müqaviləsi üzrə Borcalanın BOKT qarşısında öhdəliklərini
B18: icra etməsi üçün məsuliyyəti öz üzərinə götürürür.
B19: 1.3. Borcalan zaminliklə təmin edilmiş öhdəliyi icra etmədikdə və ya lazımınca icra etmədikdə Zamin və Borcalan BOKT qarşısında birgə məsuliyyət daşıyır.
B20: 1.4. Borcalanın BOKT qarşısındakı öhdəlikləri icra etməməsi və ya lazımınca icra etməməsi nəticəsində BOKT-a dəyən bütün zərərlərin (kredit müqaviləsi
B21: üzrə borcun, dəbbə pulu, məhkəmə xərcləri və s.) əvəzinin ödənilməsi də daxil olmaqla, "İDEAL KREDİT" BOKT qarşısında Borcalan ilə eyni həcmdə,
B22: yəni tam öhdəlik üzrə məsuliyyət daşıyır.
B23: 1.5. Bu müqavilə üzrə zaminlik | E23: =Data!I5 -> 04/2078-25 | F23: saylı kredit müqaviləsinin müddəti bitdiyi tarixdən əlavə 3 il müddətinə qüvvədədir.
B25: 2.TƏRƏFLƏRİN HÜQUQ VƏ VƏZİFƏLƏRİ
B26: 2.1. BOKT-nın hüquq və vəzifələri:
B27: 2.1.1. Borcalan BOKT qarşısında öz öhdəliklərinin icrasını lazımı səviyyədə təmin etmədikdə, BOKT Zamindən verilmiş kreditin və ona hesablanmış faiz
B28: borcunun vaxtından əvvəl qaytarılmasını tələb edə bilər.
B29: 2.1.2. Zamin Borcalanın BOKT qarşısında öhdəliklərinin icrasını təmin etdikdən sonra onun yazılı müraciəti əsasında, BOKT Borcalana qarşı tələbini təsdiq
B30: edən sənədləri Zaminə təqdim etməyə və həmin tələbi təmin edən hüquqları verməyə borcludur.
B31: 2.2. Zaminin hüquq və vəzifələri:
B32: 2.2.1. Zamin Borcalanın əvəzindən onun BOKT qarşısında olan öhdəliklərini icra etdikdən sonra, BOKT-dan Borcalana qarşı tələbini təsdiq edən sənədlərin
B33: (reqres tələblə əlaqədar) və həmin tələbi təmin edən hüquqların ona verilməsini tələb edə bilər.
B34: 2.2.2. Borcalanın əvəzindən onun BOKT-a olan öhdəliyini tam şəkildə icra etdikdən sonra BOKT-nın Borcalana qarşı həmin öhdəlik üzrə hüquqlarından tam
B35: istifadə edə bilər və s.
B36: 2.2.3. Zamin BOKT-nın tələbini ödədikdə bu barədə Borcalanı xəbərdar etməyə borcludur.
... B67: ("Zamin" əl ilə "tanış oldum razıyam" yazır və "tarixi qeyd edir")
A68: 5.TƏRƏFLƏRİN REKVİZİTLƏRİ:
B69: BOKT | K69: Borcalan
B70: "İDEAL KREDİT" BOKT MMC-nin Partnyorluq kreditləri bölməsi | I70: =Data!C23 -> Yunusov Vüqar Fikrət oğlu
B71: Müdir: Şirməmmədov Vüsal Əlyar oğlu | H71: Ünvan | J71: =Data!C29 -> NEFTÇALA RAYONU, XOL QARABUCAQ Ə/D, DÖRDLƏR KƏNDİ
B72: Hüquqi ünvan: Bakı şəhəri, F.Xoyski küç. 111"A", m.26 | H72: Ş/V № | J72: =Data!C21 -> AA5512135
B73: Faktiki ünvan: Bakı ş, Binəqədi r, 7 MKR, S.S.Axundov küç, 3123-cü məh. | H73: Verilmə tarixi | J73: =Data!E21 -> 29.10.2023 | M73: =Data!C27 -> Asan4
B74: Tel: 012 526 26 25
B75: VÖEN: | C75: 1300480591
...

Sheet TT-Akt-Kart
E4: PLASTİK KARTIN
E5: Təhvil-Təslim Aktı
B16: Bakı şəhəri | J16: =Data!E5 -> 45768
A20: Biz, aşağıda imza edənlər: BOKT "İdeal Kredit" MMC-nin adından Direktor Qubadov Qubad Baxas oğlu
A21: bir tərəfdən və fiziki şəxs ("borcalan") | E21: =Data!C23 -> Yunusov Vüqar Fikrət oğlu | J21: digər tərəfdən bu AKT-ı
A22: tərtib etdik ondan ötəri ki, | D22: =Data!E5 -> 45768 | F22: il tarixdə bağlanmış | H22: =Data!I5 -> 04/2078-25 | J22: saylı kredit müqaviləsi
A23: üzrə kredit məbləği köçürülmüş | D23: =Data!E53 -> 0 | J23: nömrəli plastik kart(lar)
A24: Bakı şəhəri, Həsən Əliyev küçəsi 34, ünvanında borcalana təhvil verilmişdir. Borcalan bu AKT-ı imzalamaqla
A25: qeyd edilən plastik kart(lar)ı təhvil aldığını təsdiq edir.
A34: Təhvil verdi: | E34: Təhvil aldı: | J34: İştirak etdi:
A35: BOKT "İdeal Kredit" MMC Əməliyyat şöbəsi | E35: =Data!C23 -> Yunusov Vüqar Fikrət oğlu | J35: BOKT "İdeal Kredit" MMC Kredit şöbəsi
A36: Bakı şəh, Həsən Əliyev küç. 34 | E36: =Data!C29 -> NEFTÇALA RAYONU, XOL QARABUCAQ Ə/D, DÖRDLƏR KƏNDİ | J36: Bakı şəh, Həsən Əliyev küç. 34
A37: VÖEN 1300480591 | E37: Ş/V | F37: =Data!C21 -> AA5512135 | J37: VÖEN 1300480591
A43: imza/tarix | E43: imza/tarix | J43: imza/tarix

Sheet Girov
A2: =Data!I5 -> 04/2078-25 | B2: Saylı kredit müqaviləsi üzrə Girov AKT-ı
C5: Tarix: | D5: =Data!E5 -> 45768
A8: Mebel alan şəxs: | B8: =Data!C23 -> Yunusov Vüqar Fikrət oğlu
B9: (Adı və soyadı)
A10: Tələb olunan kredit məbləği: | B10: =Data!C74 -> 1272 | C10: =KR!#REF! -> #REF!
A11: Telefon nömrələri: | B11: =Data!C33 -> 0703732363 müştəri,
A12: Mebelin getdiyi faktiki ünvan: | B12: Abşeron ray,Biləcəri qəs,M.Mikayılov küç,döngə 3,ev.15A. Məhəllə 35 (Oba marketin yanı)
A14: Mebel predmeti haqqında məlumat:
A15: Mebelin adı | B15: Sayı | C15: Bir vahidinin qiyməti | D15: Ümumi məbləğ
A16: Y/D Country D300-Ç160,Aytaşı | B16: 1 | C16: 5329 | D16: 5329
A17: Gold matras | B17: 1 | C17: 270 | D17: 270
A32: CƏMİ | D32: =SUM(D16:D31) -> 5599
A34: Bu akt ilə qəbul etdiyim mebel predmetləri BOKT "İDEAL KREDİT" MMC-yə olan kredit borcumu tam ödəyib
A35: qurtarana kimi "İDEAL KREDİT" BOKT-da girovdadır və onun mülkiyyətidir. Əgər kredit borcumu vaxtı-vaxtında ödəyə
A36: bilməsəm "İDEAL KREDİT" BOKT-nin əməkdaşlarının bu AKT-da qeyd olunmuş mebel predmetlərini qeyd-şərtsiz müsadirə
A37: etmələrinə heç bir etirazım yoxdur və bildirirəm ki, müsadirə anına BOKT-a olan borcum qarşılığında bu aktda qeyd edilmiş
A38: bütün mebel predmetlərini qeyri şərtsiz BOKT-nin əməkdaşlarına təhvil verəcəm və bunu aşağıda öz imzamla təsdiq edirəm.
A40: Qeyd: Borcalan kreditlə aldığı (BOKT-də girovda olan) mebeli təyinatı üzrə istifadə etməzsə (Kreditora xəbər etmədən
A41: mebeli təhvil verilmiş ünvandan fərqli ünvana daşıyarsa və ya həmin mebelin kredit borcunu tam ödəmədən digər 3-cü şəxsə
A42: satarsa / bağışlayarsa) və bununla bağlı qəsdən aldatma və etibardan sui istifadə hallarına yol verərsə Kreditor Borcalandan
A43: kreditin vaxtından əvvəl tam bağlanmasını tələb edə bilər və həmçinin cinayət məcəlləsinin 195-ci maddəsini əsas tutaraq
A44: hüquq mühafizə orqanlarına müraciət edə bilər.
A51: Borcalan
B52: (Adı və soyadı) | D52: (İmza)

Sheet Rəy
A1: Müraciət
A2: Məhsul | B2: =Data!C68 -> İstehlak mal(lar)ının alınması üçün
A3: Tarix | B3: =Data!E5 -> 45768
A4: Müştəri (S/A/A) | B4: =Data!C23 -> Yunusov Vüqar Fikrət oğlu
A5: İş yeri və vəzifəsi | B5: =Data!C43 -> Fərdi gəlirlər
A6: Əmək haqqı | B6: =Data!C49 -> 1500
A7: Əlavə gəliri | B7: =Data!C51-(B6) -> -1500
A8: Ailə gəlirləri | B8: =B6+B7 -> 0
A9: Maksimum kredit məbləği | B9: 1500
A10: Cari qalıq borc | B10: 2110
A11: Aktiv kreditlərin sayı | B11: 4 ədəd
A12: Toplam aylıq ödənişi | B12: 216
A13: Ortalama gecikmə günləri | B13: 0
A14: Cari limiti (cari borc çıxıldıqdan sonra) | B14: 4000
A15: Lizinq predmetinin dəyəri | B15: 74 azn
A16: İlkin ödəniş | B16: 0 azn
A17: Kredit məbləği | B17: =Data!C74 -> 1272
A18: Müraciət edilən kreditin müddəti (aylar) | B18: =Data!C78 -> 12
A19: Kreditin təyinatı | B19: =Data!#REF! -> #REF!
A20: Kredit Komitesine və ya İLS-ə çıxma səbəbi | B20: müştəri limiti və filialın limitini keçir
A21: KREDİT MÜTƏXƏSSİSİNİN RƏYİ
A22: Müştərinin şəxsi keyfiyyətlərini, kredit tarixcəsini və aylıq gəlirlərini nəzərə alaraq kreditin verilməsini uyğun hesab edirəm.
A35: Kredit mütəxəssisi (A.A.S): | B35: Həbibov Elvin Namiq oğlu

Sheet OPİS
G11: =Data!E5 -> 45768
B14: AZƏRBAYCAN RESPUBLIKASI
B15: Bank Olmayan Kredit Təşkilatı
B16: "İDEAL KREDİT" MMC
B21: =Data!C23 -> Yunusov Vüqar Fikrət oğlu
E23: arasında
E25: =Data!I5 -> 04/2078-25 | F25: № li
B31: Kredit Müqaviləsi
B33: Ödəmə Qrafiki
B50: Forma 4

Sheet Ödəniş Tapşırığı
A1: Ödəniş tapşırığı № 680
C2: =Data!E5 -> 45768 | P2: =TODAY() -> 45786
P3: =IF(DAY(P2)>9,DAY(P2),TEXT(,0&DAY(P2))) -> 09
A4: A1.Emitent ( ödəyən ) bank | E4: B1.Benefisiar: ( alan ) bank | P4: =IF(MONTH(P2)=1,"йанвар",(IF(MONTH(P2)=2,"феврал",(IF(MONTH(P2)=3,"март",(IF(MONTH(P2)=4,"апрел",(IF(MONTH(P2)=5,"май",(IF(MONTH(P2)=6,"ийун",(IF(MONTH(P2)=7,"ийул",""))))))))))))) -> май
A5: Adı: | B5: Azərpoçt MMC PF1 | E5: Adı: | F5: Azərpoçt MMC PF1 | J5: Ссуданын юдянилмяси цчцн | P5: =IF(P4="",(IF(MONTH(P2)=8,"август",(IF(MONTH(P2)=9,"сентйабр",(IF(MONTH(P2)=10,"октйабр",(IF(MONTH(P2)=11,"нойабр",(IF(MONTH(P2)=12,"декабр","")))))))))),"")
A6: Kodu: | B6: 691011 | E6: Kodu: | F6: 691011 | J6: Фаизин юдянилмяси цчцн | P6: =YEAR(P2) -> 2025
A7: VÖEN: | B7: 9900037711 | E7: VÖEN: | F7: 9900037711 | J7: Ссуда вя фаизин юдянилмяси цчцн | P7: =CONCATENATE(P3," ",P4," ",P5," ",P6,"-ъи ил") -> 09 май 2025-ъи ил
A8: Müxbir hesabı: | B8: AZ76NABZ01350100000000094944 | E8: Müxbir hesabı: | F8: AZ76NABZ01350100000000094944 | J8: Пластик карт кредити цзря юдяниш
A9: S.W.I.F.T. Bik: | B9: AZPOAZ22 | E9: S.W.I.F.T. Bik: | F9: AZPOAZ22
A10: A2. Ödəyən müştəri | E10: B2. Alan müştəri | I10: =B16 -> 1272
A11: Adı: | B11: "Ideal Kredit" BOKT MMC | E11: Adı: | F11: =Data!C23 -> Yunusov Vüqar Fikrət oğlu | I11: =INT(I10/10000000000) -> 0 | J11: =INT(I10/1000000000)-I11*10 -> 0 | L11: =INT(I10/100000000)-(J11*10+I11*100) -> 0 | N11: =INT(I10/10000000)-(L11*10+J11*100+I11*1000) -> 0 | O11: =INT(I10/1000000)-(I11*10000+J11*1000+L11*100+N11*10) -> 0 | Q11: =INT(I10/100000)-(I11*100000+J11*10000+L11*1000+N11*100+O11*10) -> 0 | S11: =INT(I10/10000)-(I11*1000000+J11*100000+L11*10000+N11*1000+O11*100+Q11*10) -> 0 | T11: =INT(I10/1000)-(I11*10000000+J11*1000000+L11*100000+N11*10000+O11*1000+Q11*100+S11*10) -> 1 | V11: =INT(I10/100)-(I11*100000000+J11*10000000+L11*1000000+N11*100000+O11*10000+Q11*1000+S11*100+T11*10) -> 2 | X11: =INT(I10/10)-(I11*1000000000+J11*100000000+L11*10000000+N11*1000000+O11*100000+Q11*10000+S11*1000+T11*100+V11*10) -> 7 | Y11: =INT(I10)-(I11*10000000000+J11*1000000000+L11*100000000+N11*10000000+O11*1000000+Q11*100000+S11*10000+T11*1000+V11*100+X11*10) -> 2 | Z11: =INT(I10*10)-(I11*100000000000+J11*10000000000+L11*1000000000+N11*100000000+O11*10000000+Q11*1000000+S11*100000+T11*10000+V11*1000+X11*100+Y11*10) -> 0 | AA11: =INT(I10*100)-(I11*1000000000000+J11*100000000000+L11*10000000000+N11*1000000000+O11*100000000+Q11*10000000+S11*1000000+T11*100000+V11*10000+X11*1000+Y11*100+Z11*10) -> 0
A12: Hesab №-si: | B12: AZ05AZPO91015461400420200413 | E12: Hesab №-si: | F12: =Data!F63 -> 0 | I12: =IF(I11=0," ",IF(I11=1," On ",IF(I11=2," İyirmi",IF(I11=3," Otuz",IF(I11=4," Qırx"," ")))))&IF(I11=5," Əlli",IF(I11=6," Altmış",IF(I11=7," Yetmiş",IF(I11=8," Səksən",IF(I11=9," Doxsan"," "))))) | J12: =IF(J11=0," ",IF(J11=1," bir",IF(J11=2," iki",IF(J11=3," üç",IF(J11=4," dörd"," ")))))&IF(J11=5," beş",IF(J11=6," altı",IF(J11=7," yeddi",IF(J11=8," səkkiz",IF(J11=9," doqquz"," "))))) | K12: =IF(AND(J11=0,I11=0)," "," milyard ") | L12: =IF(L11=0," ",IF(L11=1,"bir ",IF(L11=2,"iki ",IF(L11=3,"üç ",IF(L11=4,"dörd "," ")))))&IF(L11=5,"beş ",IF(L11=6,"altı ",IF(L11=7,"yeddi ",IF(L11=8,"səkkiz ",IF(L11=9,"doqquz "," "))))) | M12: =IF(L12=" "," "," yüz ") | N12: =IF(N11=0," ",IF(N11=1,"on ",IF(N11=2,"iyirmi ",IF(N11=3,"otuz ",IF(N11=4,"qırx "," ")))))&IF(N11=5,"əlli ",IF(N11=6,"altmış ",IF(N11=7,"yetmiş ",IF(N11=8,"səksən ",IF(N11=9,"doxsan "," "))))) | O12: =IF(O11=0," ",IF(O11=1,"bir",IF(O11=2,"iki",IF(O11=3,"üç",IF(O11=4,"dörd"," ")))))&IF(O11=5,"beş",IF(O11=6,"altı",IF(O11=7,"yeddi",IF(O11=8,"səkkiz",IF(O11=9,"doqquz"," "))))) | P12: =IF(AND(N11=0,L11=0,O11=0)," "," milyon ") | Q12: =IF(Q11=0," ",IF(Q11=1,"bir ",IF(Q11=2,"iki ",IF(Q11=3,"üç ",IF(Q11=4,"dörd "," ")))))&IF(Q11=5,"beş ",IF(Q11=6,"altı ",IF(Q11=7,"yeddi ",IF(Q11=8,"səkkiz ",IF(Q11=9,"doqquz "," "))))) | R12: =IF(Q12=" "," "," yüz ") | S12: =IF(S11=0," ",IF(S11=1,"on ",IF(S11=2,"iyirmi ",IF(S11=3,"otuz ",IF(S11=4,"qırx "," ")))))&IF(S11=5,"əlli ",IF(S11=6,"altmış ",IF(S11=7,"yetmiş ",IF(S11=8,"səksən ",IF(S11=9,"doxsan "," "))))) | T12: =IF(T11=0," ",IF(T11=1,"bir",IF(T11=2,"iki",IF(T11=3,"üç",IF(T11=4,"dörd"," ")))))&IF(T11=5,"beş",IF(T11=6,"altı",IF(T11=7,"yeddi",IF(T11=8,"səkkiz",IF(T11=9,"doqquz"," "))))) -> bir | U12: =IF(AND(S11=0,Q11=0,T11=0)," "," min ") -> min | V12: =IF(V11=0," ",IF(V11=1,"bir ",IF(V11=2,"iki ",IF(V11=3,"üç ",IF(V11=4,"dörd "," ")))))&IF(V11=5,"beş ",IF(V11=6,"altı ",IF(V11=7,"yeddi ",IF(V11=8,"səkkiz ",IF(V11=9,"doqquz "," "))))) -> iki | W12: =IF(V12=" "," "," yüz ") -> yüz | X12: =IF(X11=0," ",IF(X11=1," on",IF(X11=2," iyirmi",IF(X11=3," otuz",IF(X11=4," qırx"," ")))))&IF(X11=5," əlli",IF(X11=6," altmış",IF(X11=7," yetmiş",IF(X11=8," səksən",IF(X11=9," doxsan"," "))))) -> yetmiş | Y12: =IF(Y11=0," ",IF(Y11=1," bir",IF(Y11=2," iki",IF(Y11=3," üç",IF(Y11=4," dörd"," ")))))&IF(Y11=5," beş",IF(Y11=6," altı",IF(Y11=7," yeddi",IF(Y11=8," səkkiz",IF(Y11=9," doqquz"," "))))) -> iki | Z12: =IF(Z11=0," ",IF(Z11=1," он",IF(Z11=2," ийирми",IF(Z11=3," отуз",IF(Z11=4," гырх"," ")))))&IF(Z11=5," ялли",IF(Z11=6," алтмыш",IF(Z11=7," йетмиш",IF(Z11=8," сяксян",IF(Z11=9," дохсан"," "))))) | AA12: =IF(AA11=0," ",IF(AA11=1," bir",IF(AA11=2," iki",IF(AA11=3," üç",IF(AA11=4," dörd"," ")))))&IF(AA11=5," beş",IF(AA11=6," altı",IF(AA11=7," yeddi",IF(AA11=8," səkkiz",IF(AA11=9," doqquz"," ")))))
A13: VÖEN: | B13: 1300480591 | E13: VÖEN: | I13: =PROPER(I12) | J13: =IF(I12=" ",PROPER(J12),J12) | K13: =K12 | L13: =IF(AND(I12=" ",J12=" ",K12=" "),PROPER(L12),L12) | M13: =M12 | N13: =IF(AND(I12=" ",J12=" ",K12=" ",L12=" ",M12=" "),PROPER(N12),N12) | O13: =IF(AND(I12=" ",J12=" ",K12=" ",L12=" ",M12=" ",N12=" "),PROPER(O12),O12) | P13: =P12 | Q13: =IF(AND(I12=" ",J12=" ",K12=" ",L12=" ",M12=" ",N12=" ",O12=" ",P12=" "),PROPER(Q12),Q12) | R13: =R12 | S13: =IF(AND(I12=" ",J12=" ",K12=" ",L12=" ",M12=" ",N12=" ",O12=" ",P12=" ",Q12=" ",R12=" "),PROPER(S12),S12) | T13: =IF(AND(I12=" ",J12=" ",K12=" ",L12=" ",M12=" ",N12=" ",O12=" ",P12=" ",Q12=" ",R12=" ",S12=" "),PROPER(T12),T12) -> Bir | U13: =U12 -> min | V13: =IF(AND(I12=" ",J12=" ",K12=" ",L12=" ",M12=" ",N12=" ",O12=" ",P12=" ",Q12=" ",R12=" ",S12=" ",T12=" ",U12=" "),PROPER(V12),V12) -> iki | W13: =W12 -> yüz | X13: =IF(AND(I12=" ",J12=" ",K12=" ",L12=" ",M12=" ",N12=" ",O12=" ",P12=" ",Q12=" ",R12=" ",S12=" ",T12=" ",U12=" ",V12=" ",W12=" "),PROPER(X12),X12) -> yetmiş | Y13: =IF(AND(I12=" ",J12=" ",K12=" ",L12=" ",M12=" ",N12=" ",O12=" ",P12=" ",Q12=" ",R12=" ",S12=" ",T12=" ",U12=" ",V12=" ",W12=" ",X12=" "),PROPER(Y12),Y12) -> iki | Z13: =IF(AND(J12=" ",K12=" ",L12=" ",M12=" ",N12=" ",O12=" ",P12=" ",Q12=" ",R12=" ",S12=" ",T12=" ",U12=" ",V12=" ",W12=" ",X12=" ",Y12=" "),PROPER(Z12),Z12) | AA13: =IF(AND(K12=" ",L12=" ",M12=" ",N12=" ",O12=" ",P12=" ",Q12=" ",R12=" ",S12=" ",T12=" ",U12=" ",V12=" ",W12=" ",X12=" ",Y12=" ",Z12=" "),PROPER(AA12),AA12)
A14: C1. Valyuta növü: AZN | I14: =TRIM(I13&J13&K13&L13&M13&N13&O13&P13&Q13&R13&S13&T13&U13&V13&W13&X13&Y13& " manat" ) -> Bir min iki yüz yetmiş iki manat
A15: C2. Köçürülən | I15: =TRIM(Z11&AA11& " qəpik" ) -> 00 qəpik
A16: Məbləğ rəqəmlə: | B16: =Data!C74 -> 1272 | I16: =CONCATENATE(I14," ",I15) -> Bir min iki yüz yetmiş iki manat 00 qəpik
A17: Məbləğ yazı ilə: | B17: =I16 -> Bir min iki yüz yetmiş iki manat 00 qəpik
A18: D1. Ödənişin təyinatı və əsas: | C18: =KR!M5 -> 45768 | D18: tarixli | F18: kredit müqaviləsi № | G18: =Data!I5 -> 04/2078-25
A19: D2.: Ödənişlə əlaqədar
A20: Əlavə informasiya: | C20: =C18 -> 45768 | D20: tarixli | F20: kredit müqaviləsi № | G20: =G18 -> 04/2078-25
A21: Müştərinin imzaları | C21: 1. | Q21: Z13&AA13& " qəpik"
C22: 2.
A23: M.Y.
A24: Bankın imzaları: | C24: 1.
C25: 2.
A26: M.Y.
E28: İcra qeydi:
A30: Vəsaitin qeyd olunan rekvizitlər üzrə köçürülməsini öz imza və möhürümüzlə təsdiq edirik.

Sheet Məxaric
B1: “Zaminbank”АSC-nin “Bakı” filialı
B2: VÖEN 1400009111 | J2: FormaN-1
E4: XƏZİNƏ MƏXARİC ORDERİ | I4: №____________
F6: Gün | G6: Ay | H6: il
F7: 20 avqust 2014-cü il
E10: Korrespondent hesab, | G10: Analitik uçotun şifri | I10: Məbləğ | J10: Məqsədli
E11: subhesab | J11: təyinatın şifri
E12: =#REF! -> #REF! | I12: =Data!C74 -> 1272
D13: =Data!F65 -> 0
B15: Verilsin | C15: =Data!C23 -> Yunusov Vüqar Fikrət oğlu
E16: (Soyadı,adı,atasının adı)
B17: Əsas | C17: Kreditin verilməsi
C18: =Лист1!B3 -> (bir min iki yüz yetmiş (Iki ) Manat
G19: (yazı ilə məbləğ)
F21: =I12 -> 1272 | H21: AZN
B24: Bankın müdiri | H24: Baş mühasib
B25: Aldı | C25: =C18 -> (bir min iki yüz yetmiş (Iki ) Manat | I25: AZN
E26: (yazı ilə məbləğ)
C27: =F7 -> 20 avqust 2014-cü il | I27: İmza______________
C28: AZE N 06401529 ;Suraxanı RPİ 10,07,2009 | D28: AZE N | E28: =Data!D21 -> 0 | F28: =Data!C27 -> Asan4 | H28: =Data!E21 -> 29.10.2023
D29: 0
B30: Verib xəzinədar_________________
L55: qəp

Sheet Xidmət h
C2: Nağd ödəniş üçün
C3: ELAN № | F3: 1300480591
C4: =Data!E5 -> 45768
E6: Bu hesaba | F6: =KR!#REF! -> #REF!
A7: Kimdən: Fərzəlizadə Fuad Teymur oğlu | B7: =Data!C23 -> Yunusov Vüqar Fikrət oğlu | E7: köçürmək üçün №
F8: AZN
F9: =KR!#REF! -> #REF!
A10: Alanın bankı: "Zaminbank" ASC-nin 6 saylı şöbəsi | F10: rəqəmlə məbləğ
A11: Кimə: Süleymanova Aysel Namiq qızı | B11: İDEAL KREDİT BOKT
A13: Məbləğ yazı ilə: | B13: altı yüz on manat
A14: Ödənişin təyinatı: Kreditin xidmət haqqısı
A17: Ödəyənin imzası | E17: Mühasib
E18: Pulu qəbul edən xəzinədar
C21: QƏBZ №
F22: 1300480591
C23: =C4 -> 45768
A25: =A7 -> Kimdən: Fərzəlizadə Fuad Teymur oğlu | B25: =B7 -> Yunusov Vüqar Fikrət oğlu | E25: Bu hesaba | F25: =F6 -> #REF!
E26: köçürmək üçün №
F27: =F8 -> AZN
A28: =A10 -> Alanın bankı: "Zaminbank" ASC-nin 6 saylı şöbəsi | F28: =F9 -> #REF!
A29: =A11 -> Кimə: Süleymanova Aysel Namiq qızı | B29: =B11 -> İDEAL KREDİT BOKT | F29: =F10 -> rəqəmlə məbləğ
A32: =A13 -> Məbləğ yazı ilə: | B32: =B13 -> altı yüz on manat
A33: =A14 -> Ödənişin təyinatı: Kreditin xidmət haqqısı
A36: Ödəyənin imzası | E36: Mühasib
E37: Pulu qəbul edən xəzinədar
C40: ОRDER №
F41: 1300480591
C42: =C4 -> 45768
A44: =A7 -> Kimdən: Fərzəlizadə Fuad Teymur oğlu | B44: =B25 -> Yunusov Vüqar Fikrət oğlu | E44: Debet | F44: Məbləğ
E45: hes. № 1001 | F45: =F9 -> #REF!
F46: =F8 -> AZN
E47: Kredit | F47: Ümumi
A48: Аlanın bankı: "Zaminbank" ASC-nin 6 saylı şöbəsi | F48: fərdi | G48: kod
E49: =F6 -> #REF!
A50: =A11 -> Кimə: Süleymanova Aysel Namiq qızı | B50: =B11 -> İDEAL KREDİT BOKT
A52: =A14 -> Ödənişin təyinatı: Kreditin xidmət haqqısı | G52: əməl. növü
G53: ödən.təyin
G54: bank qr. №-si
A55: Mühasib | C55: Xəzinədar

Sheet Sığorta
C2: Nağd ödəniş üçün
C3: ELAN № | F3: 1300480591
C4: =Data!E5 -> 45768
E6: Bu hesaba | F6: AZ36ZAMI00041537081AZMC00001
A7: Kimdən: Fərzəlizadə Fuad Teymur oğlu | B7: =Data!C23 -> Yunusov Vüqar Fikrət oğlu | E7: köçürmək üçün №
F8: AZN
F9: 30
A10: Alanın bankı: "Zaminbank" ASC-yə | F10: rəqəmlə məbləğ
A11: Кimə: Süleymanova Aysel Namiq qızı | B11: "Paşa-Həyat" sığortaya
A13: Məbləğ yazı ilə: | B13: Otuz manat
A14: Ödənişin təyinatı: Kreditin sığorta haqqısı
